Workbook

Sheet Cover Page
C1: Practical Software Engineering Series
B2: TEST SUMMARY REPORT
D3: Version : 1.0
B5: Document Control information
B6: Faculty | C6: Faculty of Information Technology — HUFLIT
B7: Issue Date: | C7: 19-Oct-2026
B8: Author: | C8: Đặng Hải Phi (23DH112608)
B9: Confidential Class: | C9: Đồ án thực tập — nội bộ
B11: Document Revision History
B12: Date | C12: Version | D12: Description | E12: Revised by
B13: 19-Oct-2026 | C13: 1.0 | D13: Tổng hợp 100 test case (57 Automation, 43 Manual) của 3 module CRM, Sales & Invoicing, Stock. Trạng thái Manual giữ "Not Executed" cho đến khi thực thi thật. | E13: Đặng Hải Phi (23DH112608)

Sheet 0. Project Information
B2: TEST SUMMARY REPORT
B4: Project Information
B5: Project Name | C5: Kiểm thử phần mềm Dolibarr ERP & CRM 22.0.4
B6: Description | C6: Đồ án thực tập — kiểm thử Dolibarr ERP & CRM 22.0.4 trên 3 module CRM, Sales & Invoicing, Stock. Tổng 100 test case: 57 Automation (Selenium C# + MSTest, POM) và 43 Manual.
B7: Issue Date | C7: 19-Oct-2026
B8: Author | C8: Đặng Hải Phi (23DH112608)
B9: Reviewer Information | C9: Name | D9: Department | E9: Position
B10: Đặng Hải Phi (tự rà soát)
B11: Approver Information | C11: Name | D11: Department | E11: Position
B12: (điền khi có)

Sheet 1. Summary Report
B2: TEST SUMMARY REPORT — Dolibarr ERP & CRM 22.0.4
B4: OVERALL INFORMATION
B5: Test Purpose | C5: Đánh giá chất lượng chức năng Dolibarr ERP & CRM 22.0.4 (CRM, Sales & Invoicing, Stock) bằng kiểm thử tự động (Selenium C# + MSTest, POM) và kiểm thử thủ công.
B6: Number of testers | C6: 1 (Đặng Hải Phi)
B8: OVERALL STATUS
B9: Total Number of Test Cases | C9: =COUNTA('Test Log'!$A:$A)-1 | E9: Number of Defects | H9: =COUNTA('2. Defects Report'!$D:$D)-1
B10: Passed | C10: =COUNTIF('Test Log'!$G:$G,"Passed") | E10: Critical | H10: =COUNTIF('2. Defects Report'!$L:$L,"Critical")
B11: Failed | C11: =COUNTIF('Test Log'!$G:$G,"Failed") | E11: High | H11: =COUNTIF('2. Defects Report'!$L:$L,"High")
B12: Total Tests Executed (Passed + Failed) | C12: =C10+C11 | E12: Medium | H12: =COUNTIF('2. Defects Report'!$L:$L,"Medium")
B13: Not Executed | C13: =COUNTIF('Test Log'!$G:$G,"Not Executed") | E13: Minor | H13: =COUNTIF('2. Defects Report'!$L:$L,"Minor")
B14: Blocked | C14: =COUNTIF('Test Log'!$G:$G,"Blocked") | E14: Status: New (chưa xử lý) | H14: =COUNTIF('2. Defects Report'!$M:$M,"New")
B15: Execution progress | C15: =IFERROR(C12/C9,0) | E15: Status: Fixed | H15: =COUNTIF('2. Defects Report'!$M:$M,"Fixed")
B16: Pass rate (trên TC đã thực thi) | C16: =IFERROR(C10/C12,0)
B18: Test Subject | C18: Priority | D18: Total Test Cases | E18: Passed | F18: Failed | G18: Not Executed | H18: Blocked | I18: Fail Rate | J18: Total Defects | K18: Line of code (LOC) | L18: Defects fixed | M18: Fixed Rate | N18: Comments
B19: Tạo khách hàng mới | C19: High | D19: =COUNTIF('Test Log'!$D:$D,$B19) | E19: =COUNTIFS('Test Log'!$D:$D,$B19,'Test Log'!$G:$G,"Passed") | F19: =COUNTIFS('Test Log'!$D:$D,$B19,'Test Log'!$G:$G,"Failed") | G19: =COUNTIFS('Test Log'!$D:$D,$B19,'Test Log'!$G:$G,"Not Executed") | H19: =COUNTIFS('Test Log'!$D:$D,$B19,'Test Log'!$G:$G,"Blocked") | I19: =IFERROR(F19/D19,0) | J19: =COUNTIF('2. Defects Report'!$C:$C,$B19) | K19: — | L19: =COUNTIFS('2. Defects Report'!$C:$C,$B19,'2. Defects Report'!$M:$M,"Fixed") | M19: =IFERROR(L19/J19,0) | N19: Automation 13 · Manual 1 · Defect: BUG_001
B20: Chỉnh sửa thông tin khách hàng | C20: High | D20: =COUNTIF('Test Log'!$D:$D,$B20) | E20: =COUNTIFS('Test Log'!$D:$D,$B20,'Test Log'!$G:$G,"Passed") | F20: =COUNTIFS('Test Log'!$D:$D,$B20,'Test Log'!$G:$G,"Failed") | G20: =COUNTIFS('Test Log'!$D:$D,$B20,'Test Log'!$G:$G,"Not Executed") | H20: =COUNTIFS('Test Log'!$D:$D,$B20,'Test Log'!$G:$G,"Blocked") | I20: =IFERROR(F20/D20,0) | J20: =COUNTIF('2. Defects Report'!$C:$C,$B20) | K20: — | L20: =COUNTIFS('2. Defects Report'!$C:$C,$B20,'2. Defects Report'!$M:$M,"Fixed") | M20: =IFERROR(L20/J20,0) | N20: Automation 4 · Manual 1
B21: Tìm kiếm khách hàng | C21: High | D21: =COUNTIF('Test Log'!$D:$D,$B21) | E21: =COUNTIFS('Test Log'!$D:$D,$B21,'Test Log'!$G:$G,"Passed") | F21: =COUNTIFS('Test Log'!$D:$D,$B21,'Test Log'!$G:$G,"Failed") | G21: =COUNTIFS('Test Log'!$D:$D,$B21,'Test Log'!$G:$G,"Not Executed") | H21: =COUNTIFS('Test Log'!$D:$D,$B21,'Test Log'!$G:$G,"Blocked") | I21: =IFERROR(F21/D21,0) | J21: =COUNTIF('2. Defects Report'!$C:$C,$B21) | K21: — | L21: =COUNTIFS('2. Defects Report'!$C:$C,$B21,'2. Defects Report'!$M:$M,"Fixed") | M21: =IFERROR(L21/J21,0) | N21: Automation 6 · Manual 2
B22: Xóa khách hàng | C22: High | D22: =COUNTIF('Test Log'!$D:$D,$B22) | E22: =COUNTIFS('Test Log'!$D:$D,$B22,'Test Log'!$G:$G,"Passed") | F22: =COUNTIFS('Test Log'!$D:$D,$B22,'Test Log'!$G:$G,"Failed") | G22: =COUNTIFS('Test Log'!$D:$D,$B22,'Test Log'!$G:$G,"Not Executed") | H22: =COUNTIFS('Test Log'!$D:$D,$B22,'Test Log'!$G:$G,"Blocked") | I22: =IFERROR(F22/D22,0) | J22: =COUNTIF('2. Defects Report'!$C:$C,$B22) | K22: — | L22: =COUNTIFS('2. Defects Report'!$C:$C,$B22,'2. Defects Report'!$M:$M,"Fixed") | M22: =IFERROR(L22/J22,0) | N22: Automation 4 · Manual 1
B23: Báo giá thương mại | C23: High | D23: =COUNTIF('Test Log'!$D:$D,$B23) | E23: =COUNTIFS('Test Log'!$D:$D,$B23,'Test Log'!$G:$G,"Passed") | F23: =COUNTIFS('Test Log'!$D:$D,$B23,'Test Log'!$G:$G,"Failed") | G23: =COUNTIFS('Test Log'!$D:$D,$B23,'Test Log'!$G:$G,"Not Executed") | H23: =COUNTIFS('Test Log'!$D:$D,$B23,'Test Log'!$G:$G,"Blocked") | I23: =IFERROR(F23/D23,0) | J23: =COUNTIF('2. Defects Report'!$C:$C,$B23) | K23: — | L23: =COUNTIFS('2. Defects Report'!$C:$C,$B23,'2. Defects Report'!$M:$M,"Fixed") | M23: =IFERROR(L23/J23,0) | N23: Automation 11 · Manual 2
B24: Hóa đơn bán hàng chuẩn | C24: High | D24: =COUNTIF('Test Log'!$D:$D,$B24) | E24: =COUNTIFS('Test Log'!$D:$D,$B24,'Test Log'!$G:$G,"Passed") | F24: =COUNTIFS('Test Log'!$D:$D,$B24,'Test Log'!$G:$G,"Failed") | G24: =COUNTIFS('Test Log'!$D:$D,$B24,'Test Log'!$G:$G,"Not Executed") | H24: =COUNTIFS('Test Log'!$D:$D,$B24,'Test Log'!$G:$G,"Blocked") | I24: =IFERROR(F24/D24,0) | J24: =COUNTIF('2. Defects Report'!$C:$C,$B24) | K24: — | L24: =COUNTIFS('2. Defects Report'!$C:$C,$B24,'2. Defects Report'!$M:$M,"Fixed") | M24: =IFERROR(L24/J24,0) | N24: Automation 8 · Manual 1
B25: Hóa đơn đặc biệt | C25: High | D25: =COUNTIF('Test Log'!$D:$D,$B25) | E25: =COUNTIFS('Test Log'!$D:$D,$B25,'Test Log'!$G:$G,"Passed") | F25: =COUNTIFS('Test Log'!$D:$D,$B25,'Test Log'!$G:$G,"Failed") | G25: =COUNTIFS('Test Log'!$D:$D,$B25,'Test Log'!$G:$G,"Not Executed") | H25: =COUNTIFS('Test Log'!$D:$D,$B25,'Test Log'!$G:$G,"Blocked") | I25: =IFERROR(F25/D25,0) | J25: =COUNTIF('2. Defects Report'!$C:$C,$B25) | K25: — | L25: =COUNTIFS('2. Defects Report'!$C:$C,$B25,'2. Defects Report'!$M:$M,"Fixed") | M25: =IFERROR(L25/J25,0) | N25: Automation 2 · Manual 17
B26: Trừ kho tự động theo hóa đơn | C26: High | D26: =COUNTIF('Test Log'!$D:$D,$B26) | E26: =COUNTIFS('Test Log'!$D:$D,$B26,'Test Log'!$G:$G,"Passed") | F26: =COUNTIFS('Test Log'!$D:$D,$B26,'Test Log'!$G:$G,"Failed") | G26: =COUNTIFS('Test Log'!$D:$D,$B26,'Test Log'!$G:$G,"Not Executed") | H26: =COUNTIFS('Test Log'!$D:$D,$B26,'Test Log'!$G:$G,"Blocked") | I26: =IFERROR(F26/D26,0) | J26: =COUNTIF('2. Defects Report'!$C:$C,$B26) | K26: — | L26: =COUNTIFS('2. Defects Report'!$C:$C,$B26,'2. Defects Report'!$M:$M,"Fixed") | M26: =IFERROR(L26/J26,0) | N26: Automation 4 · Manual 1
B27: Điều chỉnh tồn kho thủ công | C27: High | D27: =COUNTIF('Test Log'!$D:$D,$B27) | E27: =COUNTIFS('Test Log'!$D:$D,$B27,'Test Log'!$G:$G,"Passed") | F27: =COUNTIFS('Test Log'!$D:$D,$B27,'Test Log'!$G:$G,"Failed") | G27: =COUNTIFS('Test Log'!$D:$D,$B27,'Test Log'!$G:$G,"Not Executed") | H27: =COUNTIFS('Test Log'!$D:$D,$B27,'Test Log'!$G:$G,"Blocked") | I27: =IFERROR(F27/D27,0) | J27: =COUNTIF('2. Defects Report'!$C:$C,$B27) | K27: — | L27: =COUNTIFS('2. Defects Report'!$C:$C,$B27,'2. Defects Report'!$M:$M,"Fixed") | M27: =IFERROR(L27/J27,0) | N27: Automation 3 · Manual 11
B28: Cảnh báo tồn kho tối thiểu | C28: High | D28: =COUNTIF('Test Log'!$D:$D,$B28) | E28: =COUNTIFS('Test Log'!$D:$D,$B28,'Test Log'!$G:$G,"Passed") | F28: =COUNTIFS('Test Log'!$D:$D,$B28,'Test Log'!$G:$G,"Failed") | G28: =COUNTIFS('Test Log'!$D:$D,$B28,'Test Log'!$G:$G,"Not Executed") | H28: =COUNTIFS('Test Log'!$D:$D,$B28,'Test Log'!$G:$G,"Blocked") | I28: =IFERROR(F28/D28,0) | J28: =COUNTIF('2. Defects Report'!$C:$C,$B28) | K28: — | L28: =COUNTIFS('2. Defects Report'!$C:$C,$B28,'2. Defects Report'!$M:$M,"Fixed") | M28: =IFERROR(L28/J28,0) | N28: Automation 2 · Manual 6
B29: TOTAL | D29: =SUM(D19:D28) | E29: =SUM(E19:E28) | F29: =SUM(F19:F28) | G29: =SUM(G19:G28) | H29: =SUM(H19:H28) | I29: =IFERROR(F29/D29,0) | J29: =SUM(J19:J28) | K29: 4258 | L29: =SUM(L19:L28) | M29: =IFERROR(L29/J29,0) | N29: 4.258 dòng code C# (bỏ trống & comment) đo trên 27 files POM & Test Methods.
B31: CHARTS
B50: Ghi chú: Số liệu là công thức tính từ sheet Test Log, tự cập nhật khi đổi trạng thái. TC Manual giữ "Not Executed" cho đến khi người kiểm thử thực thi và ghi Actual Result.

Sheet 2. Defects Report
B2: DEFECTS REPORT
B4: No. | C4: Test Subject | D4: Defect ID | E4: Title | F4: Steps to Reproduce | G4: Evidences | H4: Ghi chú / nguyên nhân | I4: Expected Result | J4: Actual Result | K4: Priority | L4: Severity | M4: Status | N4: Raised By | O4: Raised Date | P4: Tested on build version | Q4: Testcases Referred
B5: 1 | C5: Tạo khách hàng mới | D5: BUG_001 | E5: Redirect sau khi tạo KH chứa placeholder id=__ID__ | F5: 1. Mở /societe/card.php?action=create 2. Nhập tên KH bất kỳ, chọn loại Khách hàng (customer=1) 3. Nhấn Lưu (Save) | G5: evidence/automation/TC_CRM_010_fail_bug001.png | H5: Mã nguồn Dolibarr 22.0.4 (htdocs/societe/card.php dòng 204 và 644-648): biến backtopage gán mặc định .../societe/card.php?id=__ID__. Khi redirect, code dùng preg_replace(/--IDFORBACKTOPAGE--/, ...) thay vì __ID__, rồi nối thêm &socid={id}, khiến __ID__ bị giữ nguyên trên URL. Ảnh hưởng: không mất dữ liệu nhưng sai URL chuẩn và có thể gây lỗi khi bookmark hoặc quay lại trang. | I5: URL chuyển hướng phải là http://localhost/dolibarr/societe/card.php?socid={id} theo đặc tả UC-02 §4, không chứa placeholder __ID__. | J5: URL chuyển hướng thực tế: http://localhost/dolibarr/societe/card.php?id=__ID__&socid=109. Placeholder id=__ID__ không được thay thế bằng ID số thực tế. | K5: P2 (Medium) | L5: Minor | M5: New | N5: Đặng Hải Phi (23DH112608) | O5: 2026-10-05 | P5: Dolibarr 22.0.4 | Q5: TC_CRM_010

Sheet Evident
B1: EVIDENCE — Minh chứng kiểm thử
B3: Defect / TC | C3: Đường dẫn minh chứng (trong repo) | D3: Ghi chú
B4: BUG_001 | C4: evidence/automation/TC_CRM_010_fail_bug001.png | D4: Đã tải ảnh từ repo

Sheet Data Range
A1: Module | B1: Passed | C1: Failed | D1: Not Executed | E1: Blocked | G1: Severity | H1: Count
A2: CRM | B2: =COUNTIFS('Test Log'!$B:$B,$A2,'Test Log'!$G:$G,"Passed") | C2: =COUNTIFS('Test Log'!$B:$B,$A2,'Test Log'!$G:$G,"Failed") | D2: =COUNTIFS('Test Log'!$B:$B,$A2,'Test Log'!$G:$G,"Not Executed") | E2: =COUNTIFS('Test Log'!$B:$B,$A2,'Test Log'!$G:$G,"Blocked") | G2: Critical | H2: =COUNTIF('2. Defects Report'!$L:$L,"Critical")
A3: Sales | B3: =COUNTIFS('Test Log'!$B:$B,$A3,'Test Log'!$G:$G,"Passed") | C3: =COUNTIFS('Test Log'!$B:$B,$A3,'Test Log'!$G:$G,"Failed") | D3: =COUNTIFS('Test Log'!$B:$B,$A3,'Test Log'!$G:$G,"Not Executed") | E3: =COUNTIFS('Test Log'!$B:$B,$A3,'Test Log'!$G:$G,"Blocked") | G3: High | H3: =COUNTIF('2. Defects Report'!$L:$L,"High")
A4: Stock | B4: =COUNTIFS('Test Log'!$B:$B,$A4,'Test Log'!$G:$G,"Passed") | C4: =COUNTIFS('Test Log'!$B:$B,$A4,'Test Log'!$G:$G,"Failed") | D4: =COUNTIFS('Test Log'!$B:$B,$A4,'Test Log'!$G:$G,"Not Executed") | E4: =COUNTIFS('Test Log'!$B:$B,$A4,'Test Log'!$G:$G,"Blocked") | G4: Medium | H4: =COUNTIF('2. Defects Report'!$L:$L,"Medium")
G5: Minor | H5: =COUNTIF('2. Defects Report'!$L:$L,"Minor")
A6: Status | B6: Count
A7: Passed | B7: =COUNTIF('Test Log'!$G:$G,A7)
A8: Failed | B8: =COUNTIF('Test Log'!$G:$G,A8)
A9: Not Executed | B9: =COUNTIF('Test Log'!$G:$G,A9)
A10: Blocked | B10: =COUNTIF('Test Log'!$G:$G,A10)

Sheet Test Log
A1: Test ID | B1: Module | C1: Function ID | D1: Function name | E1: Execution | F1: Priority | G1: Status | H1: Bug ID | I1: Run date
A2: TC_CRM_005 | B2: CRM | C2: F-CRM-01 | D2: Tạo khách hàng mới | E2: Auto | F2: P1 | G2: Passed | I2: 2026-10-07
A3: TC_CRM_006 | B3: CRM | C3: F-CRM-01 | D3: Tạo khách hàng mới | E3: Auto | F3: P1 | G3: Passed | I3: 2026-10-07
A4: TC_CRM_007 | B4: CRM | C4: F-CRM-01 | D4: Tạo khách hàng mới | E4: Auto | F4: P1 | G4: Passed | I4: 2026-10-07
A5: TC_CRM_008 | B5: CRM | C5: F-CRM-01 | D5: Tạo khách hàng mới | E5: Auto | F5: P2 | G5: Passed | I5: 2026-10-07
A6: TC_CRM_009 | B6: CRM | C6: F-CRM-01 | D6: Tạo khách hàng mới | E6: Auto | F6: P2 | G6: Passed | I6: 2026-10-07
A7: TC_CRM_010 | B7: CRM | C7: F-CRM-01 | D7: Tạo khách hàng mới | E7: Auto | F7: P1 | G7: Failed | H7: BUG_001 | I7: 2026-10-07
A8: TC_CRM_011 | B8: CRM | C8: F-CRM-01 | D8: Tạo khách hàng mới | E8: Auto | F8: P2 | G8: Passed | I8: 2026-10-07
A9: TC_CRM_012 | B9: CRM | C9: F-CRM-02 | D9: Chỉnh sửa thông tin khách hàng | E9: Auto | F9: P1 | G9: Passed | I9: 2026-10-07
A10: TC_CRM_013 | B10: CRM | C10: F-CRM-03 | D10: Tìm kiếm khách hàng | E10: Auto | F10: P1 | G10: Passed | I10: 2026-10-07
A11: TC_CRM_014 | B11: CRM | C11: F-CRM-03 | D11: Tìm kiếm khách hàng | E11: Auto | F11: P2 | G11: Passed | I11: 2026-10-07
A12: TC_CRM_015 | B12: CRM | C12: F-CRM-03 | D12: Tìm kiếm khách hàng | E12: Auto | F12: P2 | G12: Passed | I12: 2026-10-07
A13: TC_CRM_016 | B13: CRM | C13: F-CRM-04 | D13: Xóa khách hàng | E13: Auto | F13: P1 | G13: Passed | I13: 2026-10-07
A14: TC_CRM_017 | B14: CRM | C14: F-CRM-01 | D14: Tạo khách hàng mới | E14: Auto | F14: P2 | G14: Passed | I14: 2026-10-19
A15: TC_CRM_018 | B15: CRM | C15: F-CRM-01 | D15: Tạo khách hàng mới | E15: Auto | F15: P2 | G15: Passed | I15: 2026-10-19
A16: TC_CRM_019 | B16: CRM | C16: F-CRM-01 | D16: Tạo khách hàng mới | E16: Auto | F16: P2 | G16: Passed | I16: 2026-10-08
A17: TC_CRM_020 | B17: CRM | C17: F-CRM-01 | D17: Tạo khách hàng mới | E17: Auto | F17: P2 | G17: Passed | I17: 2026-10-08
A18: TC_CRM_021 | B18: CRM | C18: F-CRM-04 | D18: Xóa khách hàng | E18: Auto | F18: P1 | G18: Passed | I18: 2026-10-19
A19: TC_CRM_022 | B19: CRM | C19: F-CRM-01 | D19: Tạo khách hàng mới | E19: Auto | F19: P2 | G19: Passed | I19: 2026-10-08
A20: TC_CRM_023 | B20: CRM | C20: F-CRM-03 | D20: Tìm kiếm khách hàng | E20: Auto | F20: P2 | G20: Passed | I20: 2026-10-19
A21: TC_CRM_024 | B21: CRM | C21: F-CRM-03 | D21: Tìm kiếm khách hàng | E21: Manual | F21: P1 | G21: Not Executed
A22: TC_CRM_025 | B22: CRM | C22: F-CRM-02 | D22: Chỉnh sửa thông tin khách hàng | E22: Auto | F22: P2 | G22: Not Executed
A23: TC_CRM_026 | B23: CRM | C23: F-CRM-02 | D23: Chỉnh sửa thông tin khách hàng | E23: Auto | F23: P2 | G23: Not Executed
A24: TC_CRM_027 | B24: CRM | C24: F-CRM-02 | D24: Chỉnh sửa thông tin khách hàng | E24: Manual | F24: P3 | G24: Not Executed
A25: TC_CRM_028 | B25: CRM | C25: F-CRM-02 | D25: Chỉnh sửa thông tin khách hàng | E25: Auto | F25: P1 | G25: Not Executed
A26: TC_CRM_029 | B26: CRM | C26: F-CRM-03 | D26: Tìm kiếm khách hàng | E26: Auto | F26: P1 | G26: Not Executed
A27: TC_CRM_030 | B27: CRM | C27: F-CRM-03 | D27: Tìm kiếm khách hàng | E27: Auto | F27: P2 | G27: Not Executed
A28: TC_CRM_031 | B28: CRM | C28: F-CRM-03 | D28: Tìm kiếm khách hàng | E28: Manual | F28: P2 | G28: Not Executed
A29: TC_CRM_032 | B29: CRM | C29: F-CRM-04 | D29: Xóa khách hàng | E29: Auto | F29: P1 | G29: Not Executed
A30: TC_CRM_033 | B30: CRM | C30: F-CRM-04 | D30: Xóa khách hàng | E30: Auto | F30: P2 | G30: Not Executed
A31: TC_CRM_034 | B31: CRM | C31: F-CRM-04 | D31: Xóa khách hàng | E31: Manual | F31: P3 | G31: Not Executed
A32: TC_CRM_035 | B32: CRM | C32: F-CRM-01 | D32: Tạo khách hàng mới | E32: Auto | F32: P1 | G32: Not Executed
A33: TC_CRM_036 | B33: CRM | C33: F-CRM-01 | D33: Tạo khách hàng mới | E33: Manual | F33: P2 | G33: Not Executed
A34: TC_SAL_001 | B34: Sales | C34: F-SAL-01 | D34: Báo giá thương mại | E34: Auto | F34: P1 | G34: Passed | I34: 2026-10-07
A35: TC_SAL_002 | B35: Sales | C35: F-SAL-01 | D35: Báo giá thương mại | E35: Auto | F35: P1 | G35: Passed | I35: 2026-10-07
A36: TC_SAL_003 | B36: Sales | C36: F-SAL-01 | D36: Báo giá thương mại | E36: Auto | F36: P1 | G36: Passed | I36: 2026-10-07
A37: TC_SAL_004 | B37: Sales | C37: F-SAL-01 | D37: Báo giá thương mại | E37: Auto | F37: P1 | G37: Passed | I37: 2026-10-07
A38: TC_SAL_005 | B38: Sales | C38: F-SAL-01 | D38: Báo giá thương mại | E38: Auto | F38: P1 | G38: Passed | I38: 2026-10-07
A39: TC_SAL_006 | B39: Sales | C39: F-SAL-02 | D39: Hóa đơn bán hàng chuẩn | E39: Auto | F39: P1 | G39: Passed | I39: 2026-10-07
A40: TC_SAL_007 | B40: Sales | C40: F-SAL-02 | D40: Hóa đơn bán hàng chuẩn | E40: Auto | F40: P1 | G40: Passed | I40: 2026-10-07
...
